<mujoco model="hje">
  <compiler angle="radian" meshdir="meshes/" />
  <option iterations="1" ls_iterations="5" timestep="0.002" integrator="Euler">
      <flag eulerdamp="disable"/>
  </option>

  <asset>
    <mesh name="base_link.obj" file="base_link.obj" />
    <mesh name="FL_HIP_LINK.obj" file="FL_HIP_LINK.obj" />
    <mesh name="FL_THIGH_LINK.obj" file="FL_THIGH_LINK.obj" />
    <mesh name="FL_CALF_LINK.obj" file="FL_CALF_LINK.obj" />
    <mesh name="FL_FOOT_LINK.obj" file="FL_FOOT_LINK.obj" />
    <mesh name="FR_HIP_LINK.obj" file="FR_HIP_LINK.obj" />
    <mesh name="FR_THIGH_LINK.obj" file="FR_THIGH_LINK.obj" />
    <mesh name="FR_CALF_LINK.obj" file="FR_CALF_LINK.obj" />
    <mesh name="FR_FOOT_LINK.obj" file="FR_FOOT_LINK.obj" />
    <mesh name="RL_HIP_LINK.obj" file="RL_HIP_LINK.obj" />
    <mesh name="RL_THIGH_LINK.obj" file="RL_THIGH_LINK.obj" />
    <mesh name="RL_CALF_LINK.obj" file="RL_CALF_LINK.obj" />
    <mesh name="RL_FOOT_LINK.obj" file="RL_FOOT_LINK.obj" />
    <mesh name="RR_HIP_LINK.obj" file="RR_HIP_LINK.obj" />
    <mesh name="RR_THIGH_LINK.obj" file="RR_THIGH_LINK.obj" />
    <mesh name="RR_CALF_LINK.obj" file="RR_CALF_LINK.obj" />
    <mesh name="RR_FOOT_LINK.obj" file="RR_FOOT_LINK.obj" />
    <mesh name="SHEET_METAL_LINK.obj" file="SHEET_METAL_LINK.obj" />
    <texture type="skybox" builtin="flat" rgb1="0 0 0" rgb2="0 0 0" width="512" height="3072"/>
    <texture type="2d" name="groundplane" builtin="checker" mark="edge" rgb1="0.2 0.3 0.4" rgb2="0.1 0.2 0.3" markrgb="0.8 0.8 0.8" width="300" height="300"/>
    <material name="groundplane" texture="groundplane" texuniform="true" texrepeat="5 5" reflectance="0.2"/>
  </asset>

  <worldbody>
    <light pos="0 0 10" dir="0 0 -1" diffuse="1 1 1"/>
    <light directional="true" diffuse=".8 .8 .8" pos="0 0 10" dir="0 0 -10"/>
    <geom name="floor" size="0 0 0.05" type="plane" material="groundplane" contype="0" conaffinity="1"/>

    <body name="base_link" pos="0 0 1" euler="0 0 0">
      <site name="imu" pos="0.0 0.0 0.0" group="5"/>
      <inertial pos="0 0 0" mass="21.304" diaginertia="0.1761 0.7064 0.8199"/>
      <freejoint name="root"/>
      <geom pos="0.0000 0.0000 0.0000" euler="0.0000 0.0000 0.0000" rgba="0.8667 0.9059 1.0000 1.0" group="1" type="mesh" mesh="base_link.obj" contype="0" conaffinity="0"/>
      <geom pos="0.0000 0.0000 0.0100" euler="0.0000 0.0000 0.0000" rgba="1 0 0 0.5" group="3" type="box" size="0.1500 0.1500 0.0750" />
      <body name="FL_HIP_LINK" pos="0.3085 0.0750 0.0000" euler="0.0000 0.0000 0.0000">
        <joint name="FL_HIP_JOINT" type="hinge" axis="1.0000 0.0000 0.0000" range="-1.01 1.01" damping="0" frictionloss="0"/>
        <inertial pos="0 0 0" mass="1.6116" diaginertia="0.0010 0.0021 0.0016"/>
        <geom pos="0.0000 0.0000 0.0000" euler="0.0000 0.0000 0.0000" rgba="0.8667 0.9059 1.0000 1.0" group="1" type="mesh" mesh="FL_HIP_LINK.obj" contype="0" conaffinity="0"/>
        <geom pos="0.0000 0.0200 0.0000" euler="0.0000 0.0000 0.0000" rgba="1 0 0 0.5" group="3" type="box" size="0.0450 0.0450 0.0450" />
        <body name="FL_THIGH_LINK" pos="0.0000 0.1250 0.0000" euler="0.0000 0.0000 0.0000">
          <joint name="FL_THIGH_JOINT" type="hinge" axis="0.0000 1.0000 0.0000" range="-2.36 3.14" damping="0" frictionloss="0"/>
          <inertial pos="0 0 0" mass="2.8949" diaginertia="0.0258 0.0258 0.0046"/>
          <geom pos="0.0000 0.0000 0.0000" euler="0.0000 0.0000 0.0000" rgba="0.8667 0.9059 1.0000 1.0" group="1" type="mesh" mesh="FL_THIGH_LINK.obj" contype="0" conaffinity="0"/>
          <geom pos="0.0000 0.0000 0.0000" euler="1.5710 0.0000 0.0000" rgba="1 0 0 0.5" group="3" type="cylinder" size="0.0580 0.0400" />
          <body name="FL_CALF_LINK" pos="0.0017 0.0000 -0.3300" euler="0.0000 0.0000 0.0000">
            <joint name="FL_CALF_JOINT" type="hinge" axis="0.0000 1.0000 0.0000" range="-2.8 -0.39" damping="0" frictionloss="0"/>
            <inertial pos="0 0 0" mass="0.4051" diaginertia="0.0040 0.0041 0.0001"/>
            <geom pos="0.0000 0.0000 0.0000" euler="0.0000 0.0000 0.0000" rgba="0.7922 0.8196 0.9294 1.0" group="1" type="mesh" mesh="FL_CALF_LINK.obj" contype="0" conaffinity="0"/>
            <geom pos="0.0100 0.0000 -0.0400" euler="0.0000 -0.2400 0.0000" rgba="1 0 0 0.5" group="3" type="box" size="0.0120 0.0150 0.0900" />
            <body name="FL_FOOT_LINK" pos="0.0023 0.0000 -0.3217" euler="0.0000 0.6573 0.0000">
              <inertial pos="0 0 0" mass="0.0673" diaginertia="0.0000 0.0000 0.0000"/>
              <geom pos="0.0000 0.0000 0.0000" euler="0.0000 0.0000 0.0000" rgba="0.7922 0.8196 0.9294 1.0" group="1" type="mesh" mesh="FL_FOOT_LINK.obj" contype="0" conaffinity="0"/>
              <geom pos="0.0000 0.0000 0.0000" euler="0.0000 0.0000 0.0000" rgba="1 0 0 0.5" group="3" type="sphere" size="0.0420" contype="1" conaffinity="0"/>
            </body>
          </body>
        </body>
      </body>
      <body name="FR_HIP_LINK" pos="0.3085 -0.0750 0.0000" euler="0.0000 0.0000 0.0000">
        <joint name="FR_HIP_JOINT" type="hinge" axis="1.0000 0.0000 0.0000" range="-1.01 1.01" damping="0" frictionloss="0"/>
        <inertial pos="0 0 0" mass="1.6116" diaginertia="0.0010 0.0021 0.0016"/>
        <geom pos="0.0000 0.0000 0.0000" euler="0.0000 0.0000 0.0000" rgba="0.8667 0.9059 1.0000 1.0" group="1" type="mesh" mesh="FR_HIP_LINK.obj" contype="0" conaffinity="0"/>
        <geom pos="0.0000 -0.0200 0.0000" euler="0.0000 0.0000 0.0000" rgba="1 0 0 0.5" group="3" type="box" size="0.0450 0.0450 0.0450" />
        <body name="FR_THIGH_LINK" pos="0.0000 -0.1250 0.0000" euler="0.0000 0.0000 0.0000">
          <joint name="FR_THIGH_JOINT" type="hinge" axis="0.0000 1.0000 0.0000" range="-2.36 3.14" damping="0" frictionloss="0"/>
          <inertial pos="0 0 0" mass="2.8949" diaginertia="0.0258 0.0258 0.0046"/>
          <geom pos="0.0000 0.0000 0.0000" euler="0.0000 0.0000 0.0000" rgba="0.8667 0.9059 1.0000 1.0" group="1" type="mesh" mesh="FR_THIGH_LINK.obj" contype="0" conaffinity="0"/>
          <geom pos="0.0000 0.0000 0.0000" euler="1.5710 0.0000 0.0000" rgba="1 0 0 0.5" group="3" type="cylinder" size="0.0580 0.0400" />
          <body name="FR_CALF_LINK" pos="0.0017 0.0000 -0.3300" euler="0.0000 0.0000 0.0000">
            <joint name="FR_CALF_JOINT" type="hinge" axis="0.0000 1.0000 0.0000" range="-2.8 -0.39" damping="0" frictionloss="0"/>
            <inertial pos="0 0 0" mass="0.4051" diaginertia="0.0040 0.0041 0.0001"/>
            <geom pos="0.0000 0.0000 0.0000" euler="0.0000 0.0000 0.0000" rgba="0.7922 0.8196 0.9294 1.0" group="1" type="mesh" mesh="FR_CALF_LINK.obj" contype="0" conaffinity="0"/>
            <geom pos="0.0100 0.0000 -0.0400" euler="0.0000 -0.2400 0.0000" rgba="1 0 0 0.5" group="3" type="box" size="0.0120 0.0150 0.0900" />
            <body name="FR_FOOT_LINK" pos="0.0023 0.0000 -0.3217" euler="0.0000 0.6573 0.0000">
              <inertial pos="0 0 0" mass="0.0673" diaginertia="0.0000 0.0000 0.0000"/>
              <geom pos="0.0000 0.0000 0.0000" euler="0.0000 0.0000 0.0000" rgba="0.7922 0.8196 0.9294 1.0" group="1" type="mesh" mesh="FR_FOOT_LINK.obj" contype="0" conaffinity="0"/>
              <geom pos="0.0000 0.0000 0.0000" euler="0.0000 0.0000 0.0000" rgba="1 0 0 0.5" group="3" type="sphere" size="0.0420" contype="1" conaffinity="0"/>
            </body>
          </body>
        </body>
      </body>
      <body name="RL_HIP_LINK" pos="-0.3085 0.0750 0.0000" euler="0.0000 0.0000 0.0000">
        <joint name="RL_HIP_JOINT" type="hinge" axis="1.0000 0.0000 0.0000" range="-1.01 1.01" damping="0" frictionloss="0"/>
        <inertial pos="0 0 0" mass="1.6116" diaginertia="0.0010 0.0021 0.0016"/>
        <geom pos="0.0000 0.0000 0.0000" euler="0.0000 0.0000 0.0000" rgba="0.7922 0.8196 0.9294 1.0" group="1" type="mesh" mesh="RL_HIP_LINK.obj" contype="0" conaffinity="0"/>
        <geom pos="0.0000 0.0200 0.0000" euler="0.0000 0.0000 0.0000" rgba="1 0 0 0.5" group="3" type="box" size="0.0450 0.0450 0.0450" />
        <body name="RL_THIGH_LINK" pos="0.0000 0.1250 0.0000" euler="0.0000 0.0000 0.0000">
          <joint name="RL_THIGH_JOINT" type="hinge" axis="0.0000 1.0000 0.0000" range="-2.36 3.14" damping="0" frictionloss="0"/>
          <inertial pos="0 0 0" mass="2.8949" diaginertia="0.0258 0.0258 0.0046"/>
          <geom pos="0.0000 0.0000 0.0000" euler="0.0000 0.0000 0.0000" rgba="0.8667 0.9059 1.0000 1.0" group="1" type="mesh" mesh="RL_THIGH_LINK.obj" contype="0" conaffinity="0"/>
          <geom pos="0.0000 0.0000 0.0000" euler="1.5710 0.0000 0.0000" rgba="1 0 0 0.5" group="3" type="cylinder" size="0.0580 0.0400" />
          <body name="RL_CALF_LINK" pos="0.0017 0.0000 -0.3300" euler="0.0000 0.0000 0.0000">
            <joint name="RL_CALF_JOINT" type="hinge" axis="0.0000 1.0000 0.0000" range="-2.8 -0.39" damping="0" frictionloss="0"/>
            <inertial pos="0 0 0" mass="0.4051" diaginertia="0.0040 0.0041 0.0001"/>
            <geom pos="0.0000 0.0000 0.0000" euler="0.0000 0.0000 0.0000" rgba="0.7922 0.8196 0.9294 1.0" group="1" type="mesh" mesh="RL_CALF_LINK.obj" contype="0" conaffinity="0"/>
            <geom pos="0.0100 0.0000 -0.0400" euler="0.0000 -0.2400 0.0000" rgba="1 0 0 0.5" group="3" type="box" size="0.0120 0.0150 0.0900" />
            <body name="RL_FOOT_LINK" pos="0.0023 0.0000 -0.3217" euler="0.0000 0.6573 0.0000">
              <inertial pos="0 0 0" mass="0.0673" diaginertia="0.0000 0.0000 0.0000"/>
              <geom pos="0.0000 0.0000 0.0000" euler="0.0000 0.0000 0.0000" rgba="0.7922 0.8196 0.9294 1.0" group="1" type="mesh" mesh="RL_FOOT_LINK.obj" contype="0" conaffinity="0"/>
              <geom pos="0.0000 0.0000 0.0000" euler="0.0000 0.0000 0.0000" rgba="1 0 0 0.5" group="3" type="sphere" size="0.0420" contype="1" conaffinity="0"/>
            </body>
          </body>
        </body>
      </body>
      <body name="RR_HIP_LINK" pos="-0.3085 -0.0750 0.0000" euler="0.0000 0.0000 0.0000">
        <joint name="RR_HIP_JOINT" type="hinge" axis="1.0000 0.0000 0.0000" range="-1.01 1.01" damping="0" frictionloss="0"/>
        <inertial pos="0 0 0" mass="1.6116" diaginertia="0.0010 0.0021 0.0016"/>
        <geom pos="0.0000 0.0000 0.0000" euler="0.0000 0.0000 0.0000" rgba="0.8667 0.9059 1.0000 1.0" group="1" type="mesh" mesh="RR_HIP_LINK.obj" contype="0" conaffinity="0"/>
        <geom pos="0.0000 -0.0200 0.0000" euler="0.0000 0.0000 0.0000" rgba="1 0 0 0.5" group="3" type="box" size="0.0450 0.0450 0.0450" />
        <body name="RR_THIGH_LINK" pos="0.0000 -0.1250 0.0000" euler="0.0000 0.0000 0.0000">
          <joint name="RR_THIGH_JOINT" type="hinge" axis="0.0000 1.0000 0.0000" range="-2.36 3.14" damping="0" frictionloss="0"/>
          <inertial pos="0 0 0" mass="2.8949" diaginertia="0.0258 0.0258 0.0046"/>
          <geom pos="0.0000 0.0000 0.0000" euler="0.0000 0.0000 0.0000" rgba="0.8667 0.9059 1.0000 1.0" group="1" type="mesh" mesh="RR_THIGH_LINK.obj" contype="0" conaffinity="0"/>
          <geom pos="0.0000 0.0000 0.0000" euler="1.5710 0.0000 0.0000" rgba="1 0 0 0.5" group="3" type="cylinder" size="0.0580 0.0400" />
          <body name="RR_CALF_LINK" pos="0.0017 0.0000 -0.3300" euler="0.0000 0.0000 0.0000">
            <joint name="RR_CALF_JOINT" type="hinge" axis="0.0000 1.0000 0.0000" range="-2.8 -0.39" damping="0" frictionloss="0"/>
            <inertial pos="0 0 0" mass="0.4051" diaginertia="0.0040 0.0041 0.0001"/>
            <geom pos="0.0000 0.0000 0.0000" euler="0.0000 0.0000 0.0000" rgba="0.8667 0.9059 1.0000 1.0" group="1" type="mesh" mesh="RR_CALF_LINK.obj" contype="0" conaffinity="0"/>
            <geom pos="0.0100 0.0000 -0.0400" euler="0.0000 -0.2400 0.0000" rgba="1 0 0 0.5" group="3" type="box" size="0.0120 0.0150 0.0900" />
            <body name="RR_FOOT_LINK" pos="0.0023 0.0000 -0.3217" euler="0.0000 0.6573 0.0000">
              <inertial pos="0 0 0" mass="0.0673" diaginertia="0.0000 0.0000 0.0000"/>
              <geom pos="0.0000 0.0000 0.0000" euler="0.0000 0.0000 0.0000" rgba="0.7922 0.8196 0.9294 1.0" group="1" type="mesh" mesh="RR_FOOT_LINK.obj" contype="0" conaffinity="0"/>
              <geom pos="0.0000 0.0000 0.0000" euler="0.0000 0.0000 0.0000" rgba="1 0 0 0.5" group="3" type="sphere" size="0.0420" contype="1" conaffinity="0"/>
            </body>
          </body>
        </body>
      </body>
      <body name="SHEET_METAL_LINK" pos="0.0000 0.0000 0.0000" euler="0.0000 0.0000 0.0000">
        <inertial pos="0 0 0" mass="0.97076" diaginertia="0.0090 0.0115 0.0198"/>
        <geom pos="0.0000 0.0000 0.0000" euler="0.0000 0.0000 0.0000" rgba="0.7725 0.7529 0.7333 1.0" group="1" type="mesh" mesh="SHEET_METAL_LINK.obj" contype="0" conaffinity="0"/>
      </body>
    </body>
  </worldbody>
  
  <actuator>
      <motor ctrlrange="-100.0 100.0" name="FR_HIP" joint="FR_HIP_JOINT"/>
      <motor ctrlrange="-150.0 150.0" name="FR_THIGH" joint="FR_THIGH_JOINT"/>
      <motor ctrlrange="-150.0 150.0" name="FR_CALF" joint="FR_CALF_JOINT"/>
      <motor ctrlrange="-100.0 100.0" name="FL_HIP" joint="FL_HIP_JOINT"/>
      <motor ctrlrange="-150.0 150.0" name="FL_THIGH" joint="FL_THIGH_JOINT"/>
      <motor ctrlrange="-150.0 150.0" name="FL_CALF" joint="FL_CALF_JOINT"/>
      <motor ctrlrange="-100.0 100.0" name="RR_HIP" joint="RR_HIP_JOINT"/>
      <motor ctrlrange="-150.0 150.0" name="RR_THIGH" joint="RR_THIGH_JOINT"/>
      <motor ctrlrange="-150.0 150.0" name="RR_CALF" joint="RR_CALF_JOINT"/>
      <motor ctrlrange="-100.0 100.0" name="RL_HIP" joint="RL_HIP_JOINT"/>
      <motor ctrlrange="-150.0 150.0" name="RL_THIGH" joint="RL_THIGH_JOINT"/>
      <motor ctrlrange="-150.0 150.0" name="RL_CALF" joint="RL_CALF_JOINT"/>
  </actuator>

  <sensor>
      <jointpos name="FR_HIP_POS" joint="FR_HIP_JOINT"/>
      <jointpos name="FR_THIGH_POS" joint="FR_THIGH_JOINT"/>
      <jointpos name="FR_CALF_POS" joint="FR_CALF_JOINT"/>
      <jointpos name="FL_HIP_POS" joint="FL_HIP_JOINT"/>
      <jointpos name="FL_THIGH_POS" joint="FL_THIGH_JOINT"/>
      <jointpos name="FL_CALF_POS" joint="FL_CALF_JOINT"/>
      <jointpos name="RR_HIP_POS" joint="RR_HIP_JOINT"/>
      <jointpos name="RR_THIGH_POS" joint="RR_THIGH_JOINT"/>
      <jointpos name="RR_CALF_POS" joint="RR_CALF_JOINT"/>
      <jointpos name="RL_HIP_POS" joint="RL_HIP_JOINT"/>
      <jointpos name="RL_THIGH_POS" joint="RL_THIGH_JOINT"/>
      <jointpos name="RL_CALF_POS" joint="RL_CALF_JOINT"/>

      <jointvel name="FR_HIP_VEL" joint="FR_HIP_JOINT"/>
      <jointvel name="FR_THIGH_VEL" joint="FR_THIGH_JOINT"/>
      <jointvel name="FR_CALF_VEL" joint="FR_CALF_JOINT"/>
      <jointvel name="FL_HIP_VEL" joint="FL_HIP_JOINT"/>
      <jointvel name="FL_THIGH_VEL" joint="FL_THIGH_JOINT"/>
      <jointvel name="FL_CALF_VEL" joint="FL_CALF_JOINT"/>
      <jointvel name="RR_HIP_VEL" joint="RR_HIP_JOINT"/>
      <jointvel name="RR_THIGH_VEL" joint="RR_THIGH_JOINT"/>
      <jointvel name="RR_CALF_VEL" joint="RR_CALF_JOINT"/>
      <jointvel name="RL_HIP_VEL" joint="RL_HIP_JOINT"/>
      <jointvel name="RL_THIGH_VEL" joint="RL_THIGH_JOINT"/>
      <jointvel name="RL_CALF_VEL" joint="RL_CALF_JOINT"/>


      <jointactuatorfrc name="FR_HIP_TORQUE" joint="FR_HIP_JOINT" noise="0.01"/>
      <jointactuatorfrc name="FR_THIGH_TORQUE" joint="FR_THIGH_JOINT" noise="0.01"/>
      <jointactuatorfrc name="FR_CALF_TORQUE" joint="FR_CALF_JOINT" noise="0.01"/>
      <jointactuatorfrc name="FL_HIP_TORQUE" joint="FL_HIP_JOINT" noise="0.01"/>
      <jointactuatorfrc name="FL_THIGH_TORQUE" joint="FL_THIGH_JOINT" noise="0.01"/>
      <jointactuatorfrc name="FL_CALF_TORQUE" joint="FL_CALF_JOINT" noise="0.01"/>
      <jointactuatorfrc name="RR_HIP_TORQUE" joint="RR_HIP_JOINT" noise="0.01"/>
      <jointactuatorfrc name="RR_THIGH_TORQUE" joint="RR_THIGH_JOINT" noise="0.01"/>
      <jointactuatorfrc name="RR_CALF_TORQUE" joint="RR_CALF_JOINT" noise="0.01"/>
      <jointactuatorfrc name="RL_HIP_TORQUE" joint="RL_HIP_JOINT" noise="0.01"/>
      <jointactuatorfrc name="RL_THIGH_TORQUE" joint="RL_THIGH_JOINT" noise="0.01"/>
      <jointactuatorfrc name="RL_CALF_TORQUE" joint="RL_CALF_JOINT" noise="0.01"/>

      <framequat name="imu_quat" objtype="site" objname="imu"/>
      <gyro name="imu_gyro" site="imu"/>
      <accelerometer name="imu_acc" site="imu"/>

      <framepos name="frame_pos" objtype="site" objname="imu"/>
      <framelinvel name="frame_vel" objtype="site" objname="imu"/>
  </sensor>

</mujoco>